Workbook

Sheet Лист1
H3: قائمة أسعار 2026كونتر Good Wood مفصلات TITUS/BLUM
H4: EGGER | I4: POLYLAC | J4: GLOSS MAX | K4: HPL | L4: عرض الوحدة
H5: ALVIC | J5: 5K | K5: PVC
H6: =Sheet1!I22 -> 9200 | I6: =Sheet1!H22 -> 8800 | J6: =Sheet1!G22 -> 8000 | K6: =Sheet1!E22 -> 7700 | L6: 100 | M6: الوحدات السفلية عمق 60 ارتفاع 86
H7: =Sheet1!I23 -> 8500 | I7: =Sheet1!H23 -> 8100 | J7: =Sheet1!G23 -> 7400 | K7: =Sheet1!E23 -> 7200 | L7: 90
H8: =Sheet1!I24 -> 7800 | I8: =Sheet1!H24 -> 7500 | J8: =Sheet1!G24 -> 6900 | K8: =Sheet1!E24 -> 6700 | L8: 80
H9: =Sheet1!I25 -> 7100 | I9: =Sheet1!H25 -> 6900 | J9: =Sheet1!G25 -> 6300 | K9: =Sheet1!E25 -> 6100 | L9: 70
H10: =Sheet1!I26 -> 6500 | I10: =Sheet1!H26 -> 6200 | J10: =Sheet1!G26 -> 5700 | K10: =Sheet1!E26 -> 5600 | L10: 60
H11: =Sheet1!I27 -> 5300 | I11: =Sheet1!H27 -> 5100 | J11: =Sheet1!G27 -> 4700 | K11: =Sheet1!E27 -> 4500 | L11: 50
H12: =Sheet1!I28 -> 4600 | I12: =Sheet1!H28 -> 4400 | J12: =Sheet1!G28 -> 4100 | K12: =Sheet1!E28 -> 4000 | L12: 40
H13: =Sheet1!I29 -> 3900 | I13: =Sheet1!H29 -> 3800 | J13: =Sheet1!G29 -> 3500 | K13: =Sheet1!E29 -> 3500 | L13: 30
H14: =Sheet1!I30 -> 8400 | I14: =Sheet1!H30 -> 8200 | J14: =Sheet1!G30 -> 7900 | K14: =Sheet1!E30 -> 7800 | L14: 90 | M14: زاوية مشطورة
H15: =Sheet1!I31 -> 10400 | I15: =Sheet1!H31 -> 10200 | J15: =Sheet1!G31 -> 9700 | K15: =Sheet1!E31 -> 9500 | L15: 90 | M15: ركنة حرف L
H16: =Sheet1!I32 -> 8500 | I16: =Sheet1!H32 -> 8300 | J16: =Sheet1!G32 -> 7900 | K16: =Sheet1!E32 -> 7800 | L16: 50 | M16: ادراج
H17: =Sheet1!I33 -> 8800 | I17: =Sheet1!H33 -> 8600 | J17: =Sheet1!G33 -> 8200 | K17: =Sheet1!E33 -> 8100 | L17: 60
H18: =Sheet1!I34 -> 9100 | I18: =Sheet1!H34 -> 8900 | J18: =Sheet1!G34 -> 8500 | K18: =Sheet1!E34 -> 8400 | L18: 70
H19: =Sheet1!I35 -> 9400 | I19: =Sheet1!H35 -> 9200 | J19: =Sheet1!G35 -> 8800 | K19: =Sheet1!E35 -> 8700 | L19: 80
H20: =Sheet1!I36 -> 9700 | I20: =Sheet1!H36 -> 9500 | J20: =Sheet1!G36 -> 9100 | K20: =Sheet1!E36 -> 9000 | L20: 90
H22: =Sheet1!I38 -> 7300 | I22: =Sheet1!H38 -> 6900 | J22: =Sheet1!G38 -> 6200 | K22: =Sheet1!E38 -> 5900 | L22: 100 | M22: الوحدات العلوية عمق 35 ارتفاع 75
H23: =Sheet1!I39 -> 6700 | I23: =Sheet1!H39 -> 6400 | J23: =Sheet1!G39 -> 5700 | K23: =Sheet1!E39 -> 5500 | L23: 90
H24: =Sheet1!I40 -> 6100 | I24: =Sheet1!H40 -> 5800 | J24: =Sheet1!G40 -> 5300 | K24: =Sheet1!E40 -> 5100 | L24: 80
H25: =Sheet1!I41 -> 5600 | I25: =Sheet1!H41 -> 5300 | J25: =Sheet1!G41 -> 4800 | K25: =Sheet1!E41 -> 4600 | L25: 70
H26: =Sheet1!I42 -> 5000 | I26: =Sheet1!H42 -> 4800 | J26: =Sheet1!G42 -> 4300 | K26: =Sheet1!E42 -> 4200 | L26: 60
H27: =Sheet1!I43 -> 4100 | I27: =Sheet1!H43 -> 3900 | J27: =Sheet1!G43 -> 3600 | K27: =Sheet1!E43 -> 3400 | L27: 50
H28: =Sheet1!I44 -> 3500 | I28: =Sheet1!H44 -> 3400 | J28: =Sheet1!G44 -> 3100 | K28: =Sheet1!E44 -> 3000 | L28: 40
H29: =Sheet1!I45 -> 3000 | I29: =Sheet1!H45 -> 2800 | J29: =Sheet1!G45 -> 2600 | K29: =Sheet1!E45 -> 2600 | L29: 30
H30: =Sheet1!I46 -> 5200 | I30: =Sheet1!H46 -> 5100 | J30: =Sheet1!G46 -> 4900 | K30: =Sheet1!E46 -> 4800 | L30: 60 | M30: زاوية مشطورة
H31: =Sheet1!I47 -> 6900 | I31: =Sheet1!H47 -> 6800 | J31: =Sheet1!G47 -> 6400 | K31: =Sheet1!E47 -> 6300 | L31: 60 | M31: ركنة حرف L
I33: عرض سعر للمطبخ
I34: الوحدات السفلية للمطبخ علي خامة HPL /PVC
I35: سعر اجمالي | J35: سعر الوحدة | K35: عدد | L35: عرض | M35: الوحدات السفلية
I36: =K36*J36 -> 0 | J36: =VLOOKUP(I34,Sheet1!$A$1:$B$5,2,0) -> 7700 | L36: 100
I37: =K37*J37 -> 0 | J37: =VLOOKUP(I34,Sheet1!$A$1:$P$5,3,0) -> 7200 | L37: 90
I38: =K38*J38 -> 0 | J38: =VLOOKUP(I34,Sheet1!$A$1:$P$5,4,0) -> 6700 | L38: 80
I39: =K39*J39 -> 0 | J39: =VLOOKUP(I34,Sheet1!$A$1:$P$5,5,0) -> 6100 | L39: 70
I40: =K40*J40 -> 0 | J40: =VLOOKUP(I34,Sheet1!$A$1:$P$5,6,0) -> 5600 | L40: 60
I41: =K41*J41 -> 0 | J41: =VLOOKUP(I34,Sheet1!$A$1:$P$5,7,0) -> 4500 | L41: 50
I42: =K42*J42 -> 0 | J42: =VLOOKUP(I34,Sheet1!$A$1:$P$5,8,0) -> 4000 | L42: 40
I43: =K43*J43 -> 0 | J43: =VLOOKUP(I34,Sheet1!$A$1:$P$5,9,0) -> 3500 | L43: 30
I44: =K44*J44 -> 0 | J44: =VLOOKUP(I34,Sheet1!$A$1:$P$5,10,0) -> 7800 | L44: 90 | M44: الزاوية المشطورة
...

Sheet Sheet1
A1: الوحدات السفلية للمطبخ علي خامة HPL /PVC | B1: 7700 | C1: 7200 | D1: 6700 | E1: 6100 | F1: 5600 | G1: 4500 | H1: 4000 | I1: 3500 | J1: 7800 | K1: 9500 | L1: 7800 | M1: =L1+400 -> 8200 | N1: =M1+400 -> 8600 | O1: =N1+400 -> 9000 | P1: =O1+400 -> 9400 | Q1: =(0.25*3150) -> 787.5 | R1: =MROUND(Q1,100) -> 800 | S1: 2600
A2: الوحدات السفلية للمطبخ علي خامة يلدز | B2: =F22 -> 7800 | C2: =F23 -> 7200 | D2: =F24 -> 6700 | E2: =F25 -> 6200 | F2: =F26 -> 5600 | G2: =F27 -> 4600 | H2: =F28 -> 4000 | I2: =F29 -> 3500 | J2: =F30 -> 7800 | K2: =F31 -> 9600 | L2: =F32 -> 7900 | M2: =L2+400 -> 8300 | N2: =M2+400 -> 8700 | O2: =N2+400 -> 9100 | P2: =O2+400 -> 9500 | Q2: =(0.133*6800) -> 904.4 | R2: =MROUND(Q2,100) -> 900 | S2: =R2*3 -> 2700
A3: الوحدات السفلية للمطبخ علي خامة جلوس ماكس برو/5K | B3: =G22 -> 8000 | C3: =G23 -> 7400 | D3: =G24 -> 6900 | E3: =G25 -> 6300 | F3: =G26 -> 5700 | G3: =G27 -> 4700 | H3: =G28 -> 4100 | I3: =G29 -> 3500 | J3: =G30 -> 7900 | K3: =G31 -> 9700 | L3: =G32 -> 7900 | M3: =L3+400 -> 8300 | N3: =M3+400 -> 8700 | O3: =N3+400 -> 9100 | P3: =O3+400 -> 9500 | Q3: =(0.133*7800) -> 1037.4 | R3: 1100 | S3: 3400
A4: الوحدات السفلية للمطبخ علي خامة POLYLAC | B4: =H22 -> 8800 | C4: =H23 -> 8100 | D4: =H24 -> 7500 | E4: =H25 -> 6900 | F4: =H26 -> 6200 | G4: =H27 -> 5100 | H4: =H28 -> 4400 | I4: =H29 -> 3800 | J4: =H30 -> 8200 | K4: =H31 -> 10200 | L4: =H32 -> 8300 | M4: =L4+400 -> 8700 | N4: =M4+400 -> 9100 | O4: =N4+400 -> 9500 | P4: =O4+400 -> 9900 | Q4: =(0.21*6800) -> 1428 | R4: =MROUND(Q4,100) -> 1400 | S4: 4800
A5: الوحدات السفلية للمطبخ علي خامة EGGER/ALVIC | B5: =I22 -> 9200 | C5: =I23 -> 8500 | D5: =I24 -> 7800 | E5: =I25 -> 7100 | F5: =I26 -> 6500 | G5: =I27 -> 5300 | H5: =I28 -> 4600 | I5: =I29 -> 3900 | J5: =I30 -> 8400 | K5: =I31 -> 10400 | L5: =I32 -> 8500 | M5: =L5+400 -> 8900 | N5: =M5+400 -> 9300 | O5: =N5+400 -> 9700 | P5: =O5+400 -> 10100 | Q5: =(0.21*7000) -> 1470 | R5: =MROUND(Q5,100) -> 1500 | S5: 5000
A9: الوحدات العلوية للمطبخ علي خامة HPL /PVC | B9: 5900 | C9: 5500 | D9: 5100 | E9: 4600 | F9: 4200 | G9: 3400 | H9: 3000 | I9: 2600 | J9: 4800 | K9: 6300 | L9: 500
A10: الوحدات العلوية للمطبخ علي خامة يلدز | B10: 6000 | C10: 5600 | D10: 5100 | E10: 4700 | F10: 4200 | G10: 3500 | H10: 3000 | I10: 2600 | J10: 4800 | K10: 6400 | L10: 500
A11: الوحدات العلوية للمطبخ علي خامة جلوس ماكس برو /5K | B11: 6200 | C11: 5700 | D11: 5300 | E11: 4800 | F11: 4300 | G11: 3600 | H11: 3100 | I11: 2600 | J11: 4900 | K11: 6400 | L11: 600
A12: الوحدات العلوية للمطبخ علي خامة POLYLAC | B12: 6900 | C12: 6400 | D12: 5800 | E12: 5300 | F12: 4800 | G12: 3900 | H12: 3400 | I12: 2800 | J12: 5100 | K12: 6800 | L12: 600
A13: الوحدات العلوية للمطبخ علي خامة EGGER/ALVIC | B13: 7300 | C13: 6700 | D13: 6100 | E13: 5600 | F13: 5000 | G13: 4100 | H13: 3500 | I13: 3000 | J13: 5200 | K13: 6900 | L13: 800
A15: وحدات السحارات للمطبخ علي خامة HPL /PVC | B15: =E38 -> 5900 | C15: =E39 -> 5500 | D15: =E40 -> 5100 | E15: =E41 -> 4600 | F15: =E42 -> 4200 | G15: =E43 -> 3400 | H15: =E44 -> 3000 | I15: =E45 -> 2600 | J15: =E46 -> 4800 | K15: =E47 -> 6300 | L15: 500
A16: وحدات السحارات للمطبخ علي خامة يلدز | B16: =F38 -> 6000 | C16: =F39 -> 5600 | D16: =F40 -> 5100 | E16: =F41 -> 4700 | F16: =F42 -> 4200 | G16: =F43 -> 3500 | H16: =F44 -> 3000 | I16: =F45 -> 2600 | J16: =F46 -> 4800 | K16: =F47 -> 6400 | L16: 500
A17: وحدات السحارات للمطبخ علي خامة جلوس ماكس برو/5K | B17: =G38 -> 6200 | C17: =G39 -> 5700 | D17: =G40 -> 5300 | E17: =G41 -> 4800 | F17: =G42 -> 4300 | G17: =G43 -> 3600 | H17: =G44 -> 3100 | I17: =G45 -> 2600 | J17: =G46 -> 4900 | K17: =G47 -> 6400 | L17: 600
A18: وحدات السحارات للمطبخ علي خامة POLYLAC | B18: =H38 -> 6900 | C18: =H39 -> 6400 | D18: =H40 -> 5800 | E18: =H41 -> 5300 | F18: =H42 -> 4800 | G18: =H43 -> 3900 | H18: =H44 -> 3400 | I18: =H45 -> 2800 | J18: =H46 -> 5100 | K18: =H47 -> 6800 | L18: 600
A19: وحدات السحارات للمطبخ علي خامة EGGER/ALVIC | B19: =I38 -> 7300 | C19: =I39 -> 6700 | D19: =I40 -> 6100 | E19: =I41 -> 5600 | F19: =I42 -> 5000 | G19: =I43 -> 4100 | H19: =I44 -> 3500 | I19: =I45 -> 3000 | J19: =I46 -> 5200 | K19: =I47 -> 6900 | L19: 800
E21: HPL | F21: PVC | G21: لامي جلوس | H21: يوفي لاك | I21: بولي لاك | N21: HPL | O21: يلدز | P21: جلوس ماكس | Q21: يوفي لاك | R21: بولي لاك
E22: 7700 | F22: 7800 | G22: 8000 | H22: 8800 | I22: 9200 | K22: 100 | N22: 6900 | O22: 7200 | P22: 7400 | Q22: 8000 | R22: 8300
E23: 7200 | F23: 7200 | G23: 7400 | H23: 8100 | I23: 8500 | K23: 90 | N23: 6400 | O23: 6700 | P23: 6800 | Q23: 7400 | R23: 7700
E24: 6700 | F24: 6700 | G24: 6900 | H24: 7500 | I24: 7800 | K24: 80 | N24: 6000 | O24: 6200 | P24: 6300 | Q24: 6900 | R24: 7100
E25: 6100 | F25: 6200 | G25: 6300 | H25: 6900 | I25: 7100 | K25: 70 | N25: 5500 | O25: 5700 | P25: 5800 | Q25: 6300 | R25: 6500
E26: 5600 | F26: 5600 | G26: 5700 | H26: 6200 | I26: 6500 | K26: 60 | N26: 5000 | O26: 5200 | P26: 5300 | Q26: 5700 | R26: 5900
E27: 4500 | F27: 4600 | G27: 4700 | H27: 5100 | I27: 5300 | K27: 50 | N27: 4000 | O27: 4200 | P27: 4300 | Q27: 4600 | R27: 4800
E28: 4000 | F28: 4000 | G28: 4100 | H28: 4400 | I28: 4600 | K28: 40 | N28: 3600 | O28: 3700 | P28: 3800 | Q28: 4000 | R28: 4100
E29: 3500 | F29: 3500 | G29: 3500 | H29: 3800 | I29: 3900 | K29: 30 | N29: 3100 | O29: 3200 | P29: 3200 | Q29: 3400 | R29: 3500
E30: 7800 | F30: 7800 | G30: 7900 | H30: 8200 | I30: 8400 | K30: 90 | N30: 7000 | O30: 7200 | P30: 7200 | Q30: 7500 | R30: 7600
E31: 9500 | F31: 9600 | G31: 9700 | H31: 10200 | I31: 10400 | K31: 90 | N31: 8700 | O31: 8900 | P31: 9000 | Q31: 9400 | R31: 9600
E32: 7800 | F32: 7900 | G32: 7900 | H32: 8300 | I32: 8500 | K32: 50 | N32: 7200 | O32: 7300 | P32: 7400 | Q32: 7800 | R32: 7900
E33: =E32+300 -> 8100 | F33: =F32+300 -> 8200 | G33: =G32+300 -> 8200 | H33: =H32+300 -> 8600 | I33: =I32+300 -> 8800 | K33: 60
E34: =E33+300 -> 8400 | F34: =F33+300 -> 8500 | G34: =G33+300 -> 8500 | H34: =H33+300 -> 8900 | I34: =I33+300 -> 9100 | K34: 70 | N34: 0 | O34: 0 | P34: 0 | Q34: 0 | R34: 0
E35: =E34+300 -> 8700 | F35: =F34+300 -> 8800 | G35: =G34+300 -> 8800 | H35: =H34+300 -> 9200 | I35: =I34+300 -> 9400 | K35: 80 | N35: 5600 | O35: 5700 | P35: 6000 | Q35: 6600 | R35: 7000
E36: =E35+300 -> 9000 | F36: =F35+300 -> 9100 | G36: =G35+300 -> 9100 | H36: =H35+300 -> 9500 | I36: =I35+300 -> 9700 | K36: 90 | N36: 5200 | O36: 5300 | P36: 5500 | Q36: 6100 | R36: 6400
N37: 4700 | O37: 4800 | P37: 5100 | Q37: 5500 | R37: 5900
E38: 5900 | F38: 6000 | G38: 6200 | H38: 6900 | I38: 7300 | K38: 100 | N38: 4300 | O38: 4400 | P38: 4600 | Q38: 5000 | R38: 5300
E39: 5500 | F39: 5600 | G39: 5700 | H39: 6400 | I39: 6700 | K39: 90 | N39: 3900 | O39: 4000 | P39: 4200 | Q39: 4500 | R39: 4800
E40: 5100 | F40: 5100 | G40: 5300 | H40: 5800 | I40: 6100 | K40: 80 | N40: 3200 | O40: 3300 | P40: 3400 | Q40: 3700 | R40: 3900
E41: 4600 | F41: 4700 | G41: 4800 | H41: 5300 | I41: 5600 | K41: 70 | N41: 2800 | O41: 2900 | P41: 3000 | Q41: 3200 | R41: 3400
E42: 4200 | F42: 4200 | G42: 4300 | H42: 4800 | I42: 5000 | K42: 60 | N42: 2400 | O42: 2400 | P42: 2500 | Q42: 2700 | R42: 2800
E43: 3400 | F43: 3500 | G43: 3600 | H43: 3900 | I43: 4100 | K43: 50 | N43: 4500 | O43: 4500 | P43: 4600 | Q43: 4800 | R43: 4900
E44: 3000 | F44: 3000 | G44: 3100 | H44: 3400 | I44: 3500 | K44: 40 | N44: 6000 | O44: 6100 | P44: 6200 | Q44: 6500 | R44: 6600
E45: 2600 | F45: 2600 | G45: 2600 | H45: 2800 | I45: 3000 | K45: 30
...
